2023-12-15 22:07:44,521  syncdbconnect.py 29 [INFO] Configurations Loaded Successfully.
2023-12-15 22:07:44,522  syncdbconnect.py 30 [INFO] DB Connection Module Loaded Successfully.
2023-12-15 22:07:44,522  syncdbconnect.py 31 [INFO] currentpath: C:\Users\Chon791AD14\OneDrive - Ramco Systems Limited\Documents\NLP\PythonScript\Sync_to_Elasticsearch\elasticsearch
2023-12-15 22:07:44,522  syncdbconnect.py 32 [INFO] configpath: C:\Users\Chon791AD14\OneDrive - Ramco Systems Limited\Documents\NLP\PythonScript\Sync_to_Elasticsearch\elasticsearch\config.ini
2023-12-15 22:07:48,592  _transport.py 359 [INFO] HEAD http://localhost:9200/ [status:N/A duration:4.065s]
2023-12-15 22:07:48,592  _transport.py 359 [INFO] HEAD http://localhost:9200/ [status:N/A duration:4.065s]
2023-12-15 22:07:48,592  _node_pool.py 246 [WARNING] Node <Urllib3HttpNode(http://localhost:9200)> has failed for 1 times in a row, putting on 1 second timeout
2023-12-15 22:07:48,592  _node_pool.py 246 [WARNING] Node <Urllib3HttpNode(http://localhost:9200)> has failed for 1 times in a row, putting on 1 second timeout
2023-12-15 22:07:48,593  _transport.py 396 [WARNING] Retrying request after failure (attempt 0 of 3)
Traceback (most recent call last):
  File "C:\Users\Chon791AD14\AppData\Local\Programs\Python\Python39\lib\site-packages\elastic_transport\_transport.py", line 329, in perform_request
    meta, raw_data = node.perform_request(
  File "C:\Users\Chon791AD14\AppData\Local\Programs\Python\Python39\lib\site-packages\elastic_transport\_node\_http_urllib3.py", line 199, in perform_request
    raise err from None
elastic_transport.ConnectionError: Connection error caused by: NewConnectionError(<urllib3.connection.HTTPConnection object at 0x00000188524BB670>: Failed to establish a new connection: [WinError 10061] No connection could be made because the target machine actively refused it)
2023-12-15 22:07:48,593  _transport.py 396 [WARNING] Retrying request after failure (attempt 0 of 3)
Traceback (most recent call last):
  File "C:\Users\Chon791AD14\AppData\Local\Programs\Python\Python39\lib\site-packages\elastic_transport\_transport.py", line 329, in perform_request
    meta, raw_data = node.perform_request(
  File "C:\Users\Chon791AD14\AppData\Local\Programs\Python\Python39\lib\site-packages\elastic_transport\_node\_http_urllib3.py", line 199, in perform_request
    raise err from None
elastic_transport.ConnectionError: Connection error caused by: NewConnectionError(<urllib3.connection.HTTPConnection object at 0x00000188524BB670>: Failed to establish a new connection: [WinError 10061] No connection could be made because the target machine actively refused it)
2023-12-15 22:07:52,645  _transport.py 359 [INFO] HEAD http://localhost:9200/ [status:N/A duration:4.023s]
2023-12-15 22:07:52,645  _transport.py 359 [INFO] HEAD http://localhost:9200/ [status:N/A duration:4.023s]
2023-12-15 22:07:52,646  _node_pool.py 246 [WARNING] Node <Urllib3HttpNode(http://localhost:9200)> has failed for 2 times in a row, putting on 2 second timeout
2023-12-15 22:07:52,646  _node_pool.py 246 [WARNING] Node <Urllib3HttpNode(http://localhost:9200)> has failed for 2 times in a row, putting on 2 second timeout
2023-12-15 22:07:52,646  _transport.py 396 [WARNING] Retrying request after failure (attempt 1 of 3)
Traceback (most recent call last):
  File "C:\Users\Chon791AD14\AppData\Local\Programs\Python\Python39\lib\site-packages\elastic_transport\_transport.py", line 329, in perform_request
    meta, raw_data = node.perform_request(
  File "C:\Users\Chon791AD14\AppData\Local\Programs\Python\Python39\lib\site-packages\elastic_transport\_node\_http_urllib3.py", line 199, in perform_request
    raise err from None
elastic_transport.ConnectionError: Connection error caused by: NewConnectionError(<urllib3.connection.HTTPConnection object at 0x00000188524BB9D0>: Failed to establish a new connection: [WinError 10061] No connection could be made because the target machine actively refused it)
2023-12-15 22:07:52,646  _transport.py 396 [WARNING] Retrying request after failure (attempt 1 of 3)
Traceback (most recent call last):
  File "C:\Users\Chon791AD14\AppData\Local\Programs\Python\Python39\lib\site-packages\elastic_transport\_transport.py", line 329, in perform_request
    meta, raw_data = node.perform_request(
  File "C:\Users\Chon791AD14\AppData\Local\Programs\Python\Python39\lib\site-packages\elastic_transport\_node\_http_urllib3.py", line 199, in perform_request
    raise err from None
elastic_transport.ConnectionError: Connection error caused by: NewConnectionError(<urllib3.connection.HTTPConnection object at 0x00000188524BB9D0>: Failed to establish a new connection: [WinError 10061] No connection could be made because the target machine actively refused it)
2023-12-15 22:07:52,649  _node_pool.py 309 [INFO] Resurrected node <Urllib3HttpNode(http://localhost:9200)> (force=False)
2023-12-15 22:07:52,649  _node_pool.py 309 [INFO] Resurrected node <Urllib3HttpNode(http://localhost:9200)> (force=False)
2023-12-15 22:07:56,713  _transport.py 359 [INFO] HEAD http://localhost:9200/ [status:N/A duration:4.064s]
2023-12-15 22:07:56,713  _transport.py 359 [INFO] HEAD http://localhost:9200/ [status:N/A duration:4.064s]
2023-12-15 22:07:56,714  _node_pool.py 246 [WARNING] Node <Urllib3HttpNode(http://localhost:9200)> has failed for 3 times in a row, putting on 4 second timeout
2023-12-15 22:07:56,714  _node_pool.py 246 [WARNING] Node <Urllib3HttpNode(http://localhost:9200)> has failed for 3 times in a row, putting on 4 second timeout
2023-12-15 22:07:56,715  _transport.py 396 [WARNING] Retrying request after failure (attempt 2 of 3)
Traceback (most recent call last):
  File "C:\Users\Chon791AD14\AppData\Local\Programs\Python\Python39\lib\site-packages\elastic_transport\_transport.py", line 329, in perform_request
    meta, raw_data = node.perform_request(
  File "C:\Users\Chon791AD14\AppData\Local\Programs\Python\Python39\lib\site-packages\elastic_transport\_node\_http_urllib3.py", line 199, in perform_request
    raise err from None
elastic_transport.ConnectionError: Connection error caused by: NewConnectionError(<urllib3.connection.HTTPConnection object at 0x00000188524BBE80>: Failed to establish a new connection: [WinError 10061] No connection could be made because the target machine actively refused it)
2023-12-15 22:07:56,715  _transport.py 396 [WARNING] Retrying request after failure (attempt 2 of 3)
Traceback (most recent call last):
  File "C:\Users\Chon791AD14\AppData\Local\Programs\Python\Python39\lib\site-packages\elastic_transport\_transport.py", line 329, in perform_request
    meta, raw_data = node.perform_request(
  File "C:\Users\Chon791AD14\AppData\Local\Programs\Python\Python39\lib\site-packages\elastic_transport\_node\_http_urllib3.py", line 199, in perform_request
    raise err from None
elastic_transport.ConnectionError: Connection error caused by: NewConnectionError(<urllib3.connection.HTTPConnection object at 0x00000188524BBE80>: Failed to establish a new connection: [WinError 10061] No connection could be made because the target machine actively refused it)
2023-12-15 22:07:56,716  _node_pool.py 309 [INFO] Resurrected node <Urllib3HttpNode(http://localhost:9200)> (force=False)
2023-12-15 22:07:56,716  _node_pool.py 309 [INFO] Resurrected node <Urllib3HttpNode(http://localhost:9200)> (force=False)
2023-12-15 22:08:00,779  _transport.py 359 [INFO] HEAD http://localhost:9200/ [status:N/A duration:4.063s]
2023-12-15 22:08:00,779  _transport.py 359 [INFO] HEAD http://localhost:9200/ [status:N/A duration:4.063s]
2023-12-15 22:08:00,781  _node_pool.py 246 [WARNING] Node <Urllib3HttpNode(http://localhost:9200)> has failed for 4 times in a row, putting on 8 second timeout
2023-12-15 22:08:00,781  _node_pool.py 246 [WARNING] Node <Urllib3HttpNode(http://localhost:9200)> has failed for 4 times in a row, putting on 8 second timeout
2023-12-15 22:08:00,781  main.py 42 [INFO] False
2023-12-15 22:08:00,781  main.py 42 [INFO] False
2023-12-15 22:08:39,601  syncdbconnect.py 29 [INFO] Configurations Loaded Successfully.
2023-12-15 22:08:39,602  syncdbconnect.py 30 [INFO] DB Connection Module Loaded Successfully.
2023-12-15 22:08:39,603  syncdbconnect.py 31 [INFO] currentpath: C:\Users\Chon791AD14\OneDrive - Ramco Systems Limited\Documents\NLP\PythonScript\Sync_to_Elasticsearch\elasticsearch
2023-12-15 22:08:39,603  syncdbconnect.py 32 [INFO] configpath: C:\Users\Chon791AD14\OneDrive - Ramco Systems Limited\Documents\NLP\PythonScript\Sync_to_Elasticsearch\elasticsearch\config.ini
2023-12-15 22:08:43,688  _transport.py 359 [INFO] HEAD http://localhost:9200/ [status:N/A duration:4.079s]
2023-12-15 22:08:43,688  _transport.py 359 [INFO] HEAD http://localhost:9200/ [status:N/A duration:4.079s]
2023-12-15 22:08:43,689  _node_pool.py 246 [WARNING] Node <Urllib3HttpNode(http://localhost:9200)> has failed for 1 times in a row, putting on 1 second timeout
2023-12-15 22:08:43,689  _node_pool.py 246 [WARNING] Node <Urllib3HttpNode(http://localhost:9200)> has failed for 1 times in a row, putting on 1 second timeout
2023-12-15 22:08:43,689  _transport.py 396 [WARNING] Retrying request after failure (attempt 0 of 3)
Traceback (most recent call last):
  File "C:\Users\Chon791AD14\AppData\Local\Programs\Python\Python39\lib\site-packages\elastic_transport\_transport.py", line 329, in perform_request
    meta, raw_data = node.perform_request(
  File "C:\Users\Chon791AD14\AppData\Local\Programs\Python\Python39\lib\site-packages\elastic_transport\_node\_http_urllib3.py", line 199, in perform_request
    raise err from None
elastic_transport.ConnectionError: Connection error caused by: NewConnectionError(<urllib3.connection.HTTPConnection object at 0x000001D5F99BA670>: Failed to establish a new connection: [WinError 10061] No connection could be made because the target machine actively refused it)
2023-12-15 22:08:43,689  _transport.py 396 [WARNING] Retrying request after failure (attempt 0 of 3)
Traceback (most recent call last):
  File "C:\Users\Chon791AD14\AppData\Local\Programs\Python\Python39\lib\site-packages\elastic_transport\_transport.py", line 329, in perform_request
    meta, raw_data = node.perform_request(
  File "C:\Users\Chon791AD14\AppData\Local\Programs\Python\Python39\lib\site-packages\elastic_transport\_node\_http_urllib3.py", line 199, in perform_request
    raise err from None
elastic_transport.ConnectionError: Connection error caused by: NewConnectionError(<urllib3.connection.HTTPConnection object at 0x000001D5F99BA670>: Failed to establish a new connection: [WinError 10061] No connection could be made because the target machine actively refused it)
2023-12-15 22:08:47,776  _transport.py 359 [INFO] HEAD http://localhost:9200/ [status:N/A duration:4.059s]
2023-12-15 22:08:47,776  _transport.py 359 [INFO] HEAD http://localhost:9200/ [status:N/A duration:4.059s]
2023-12-15 22:08:47,777  _node_pool.py 246 [WARNING] Node <Urllib3HttpNode(http://localhost:9200)> has failed for 2 times in a row, putting on 2 second timeout
2023-12-15 22:08:47,777  _node_pool.py 246 [WARNING] Node <Urllib3HttpNode(http://localhost:9200)> has failed for 2 times in a row, putting on 2 second timeout
2023-12-15 22:08:47,778  _transport.py 396 [WARNING] Retrying request after failure (attempt 1 of 3)
Traceback (most recent call last):
  File "C:\Users\Chon791AD14\AppData\Local\Programs\Python\Python39\lib\site-packages\elastic_transport\_transport.py", line 329, in perform_request
    meta, raw_data = node.perform_request(
  File "C:\Users\Chon791AD14\AppData\Local\Programs\Python\Python39\lib\site-packages\elastic_transport\_node\_http_urllib3.py", line 199, in perform_request
    raise err from None
elastic_transport.ConnectionError: Connection error caused by: NewConnectionError(<urllib3.connection.HTTPConnection object at 0x000001D5F99BA9D0>: Failed to establish a new connection: [WinError 10061] No connection could be made because the target machine actively refused it)
2023-12-15 22:08:47,778  _transport.py 396 [WARNING] Retrying request after failure (attempt 1 of 3)
Traceback (most recent call last):
  File "C:\Users\Chon791AD14\AppData\Local\Programs\Python\Python39\lib\site-packages\elastic_transport\_transport.py", line 329, in perform_request
    meta, raw_data = node.perform_request(
  File "C:\Users\Chon791AD14\AppData\Local\Programs\Python\Python39\lib\site-packages\elastic_transport\_node\_http_urllib3.py", line 199, in perform_request
    raise err from None
elastic_transport.ConnectionError: Connection error caused by: NewConnectionError(<urllib3.connection.HTTPConnection object at 0x000001D5F99BA9D0>: Failed to establish a new connection: [WinError 10061] No connection could be made because the target machine actively refused it)
2023-12-15 22:08:47,779  _node_pool.py 309 [INFO] Resurrected node <Urllib3HttpNode(http://localhost:9200)> (force=False)
2023-12-15 22:08:47,779  _node_pool.py 309 [INFO] Resurrected node <Urllib3HttpNode(http://localhost:9200)> (force=False)
2023-12-15 22:08:51,866  _transport.py 359 [INFO] HEAD http://localhost:9200/ [status:N/A duration:4.086s]
2023-12-15 22:08:51,866  _transport.py 359 [INFO] HEAD http://localhost:9200/ [status:N/A duration:4.086s]
2023-12-15 22:08:51,867  _node_pool.py 246 [WARNING] Node <Urllib3HttpNode(http://localhost:9200)> has failed for 3 times in a row, putting on 4 second timeout
2023-12-15 22:08:51,867  _node_pool.py 246 [WARNING] Node <Urllib3HttpNode(http://localhost:9200)> has failed for 3 times in a row, putting on 4 second timeout
2023-12-15 22:08:51,867  _transport.py 396 [WARNING] Retrying request after failure (attempt 2 of 3)
Traceback (most recent call last):
  File "C:\Users\Chon791AD14\AppData\Local\Programs\Python\Python39\lib\site-packages\elastic_transport\_transport.py", line 329, in perform_request
    meta, raw_data = node.perform_request(
  File "C:\Users\Chon791AD14\AppData\Local\Programs\Python\Python39\lib\site-packages\elastic_transport\_node\_http_urllib3.py", line 199, in perform_request
    raise err from None
elastic_transport.ConnectionError: Connection error caused by: NewConnectionError(<urllib3.connection.HTTPConnection object at 0x000001D5F99BAE80>: Failed to establish a new connection: [WinError 10061] No connection could be made because the target machine actively refused it)
2023-12-15 22:08:51,867  _transport.py 396 [WARNING] Retrying request after failure (attempt 2 of 3)
Traceback (most recent call last):
  File "C:\Users\Chon791AD14\AppData\Local\Programs\Python\Python39\lib\site-packages\elastic_transport\_transport.py", line 329, in perform_request
    meta, raw_data = node.perform_request(
  File "C:\Users\Chon791AD14\AppData\Local\Programs\Python\Python39\lib\site-packages\elastic_transport\_node\_http_urllib3.py", line 199, in perform_request
    raise err from None
elastic_transport.ConnectionError: Connection error caused by: NewConnectionError(<urllib3.connection.HTTPConnection object at 0x000001D5F99BAE80>: Failed to establish a new connection: [WinError 10061] No connection could be made because the target machine actively refused it)
2023-12-15 22:08:51,869  _node_pool.py 309 [INFO] Resurrected node <Urllib3HttpNode(http://localhost:9200)> (force=False)
2023-12-15 22:08:51,869  _node_pool.py 309 [INFO] Resurrected node <Urllib3HttpNode(http://localhost:9200)> (force=False)
2023-12-15 22:08:55,930  _transport.py 359 [INFO] HEAD http://localhost:9200/ [status:N/A duration:4.061s]
2023-12-15 22:08:55,930  _transport.py 359 [INFO] HEAD http://localhost:9200/ [status:N/A duration:4.061s]
2023-12-15 22:08:55,931  _node_pool.py 246 [WARNING] Node <Urllib3HttpNode(http://localhost:9200)> has failed for 4 times in a row, putting on 8 second timeout
2023-12-15 22:08:55,931  _node_pool.py 246 [WARNING] Node <Urllib3HttpNode(http://localhost:9200)> has failed for 4 times in a row, putting on 8 second timeout
2023-12-15 22:08:55,931  main.py 42 [INFO] False
2023-12-15 22:08:55,931  main.py 42 [INFO] False
2023-12-15 22:08:55,954  syncdbconnect.py 67 [INFO] CONNECTING SQL DATABASE SERVER: localhost, DATABASE: 
2023-12-15 22:08:55,954  syncdbconnect.py 67 [INFO] CONNECTING SQL DATABASE SERVER: localhost, DATABASE: 
2023-12-15 22:09:29,126  syncdbconnect.py 73 [ERROR] FAILED! Please Check details. [DRIVER={ODBC Driver 17 for SQL Server};SERVER=localhost;DATABASE=;UID=admin;PWD=localhost;Trusted_Connection=yes;
Traceback (most recent call last):
  File "C:\Users\Chon791AD14\OneDrive - Ramco Systems Limited\Documents\NLP\PythonScript\Sync_to_Elasticsearch\elasticsearch\elasticsearch\syncdbconnect.py", line 68, in pyodbc_database_connection
    cnxn = pyodbc.connect(
pyodbc.OperationalError: ('08001', '[08001] [Microsoft][ODBC Driver 17 for SQL Server]Named Pipes Provider: Could not open a connection to SQL Server [2].  (2) (SQLDriverConnect); [08001] [Microsoft][ODBC Driver 17 for SQL Server]Login timeout expired (0); [08001] [Microsoft][ODBC Driver 17 for SQL Server]A network-related or instance-specific error has occurred while establishing a connection to SQL Server. Server is not found or not accessible. Check if instance name is correct and if SQL Server is configured to allow remote connections. For more information see SQL Server Books Online. (2)')
2023-12-15 22:09:29,126  syncdbconnect.py 73 [ERROR] FAILED! Please Check details. [DRIVER={ODBC Driver 17 for SQL Server};SERVER=localhost;DATABASE=;UID=admin;PWD=localhost;Trusted_Connection=yes;
Traceback (most recent call last):
  File "C:\Users\Chon791AD14\OneDrive - Ramco Systems Limited\Documents\NLP\PythonScript\Sync_to_Elasticsearch\elasticsearch\elasticsearch\syncdbconnect.py", line 68, in pyodbc_database_connection
    cnxn = pyodbc.connect(
pyodbc.OperationalError: ('08001', '[08001] [Microsoft][ODBC Driver 17 for SQL Server]Named Pipes Provider: Could not open a connection to SQL Server [2].  (2) (SQLDriverConnect); [08001] [Microsoft][ODBC Driver 17 for SQL Server]Login timeout expired (0); [08001] [Microsoft][ODBC Driver 17 for SQL Server]A network-related or instance-specific error has occurred while establishing a connection to SQL Server. Server is not found or not accessible. Check if instance name is correct and if SQL Server is configured to allow remote connections. For more information see SQL Server Books Online. (2)')
2023-12-15 22:09:29,130  syncdbconnect.py 75 [ERROR] Error Occurred at: ('08001', '[08001] [Microsoft][ODBC Driver 17 for SQL Server]Named Pipes Provider: Could not open a connection to SQL Server [2].  (2) (SQLDriverConnect); [08001] [Microsoft][ODBC Driver 17 for SQL Server]Login timeout expired (0); [08001] [Microsoft][ODBC Driver 17 for SQL Server]A network-related or instance-specific error has occurred while establishing a connection to SQL Server. Server is not found or not accessible. Check if instance name is correct and if SQL Server is configured to allow remote connections. For more information see SQL Server Books Online. (2)') Data Obtained: {'server': 'localhost', 'database': '', 'username': 'admin', 'password': 'localhost', 'e': OperationalError('08001', '[08001] [Microsoft][ODBC Driver 17 for SQL Server]Named Pipes Provider: Could not open a connection to SQL Server [2].  (2) (SQLDriverConnect); [08001] [Microsoft][ODBC Driver 17 for SQL Server]Login timeout expired (0); [08001] [Microsoft][ODBC Driver 17 for SQL Server]A network-related or instance-specific error has occurred while establishing a connection to SQL Server. Server is not found or not accessible. Check if instance name is correct and if SQL Server is configured to allow remote connections. For more information see SQL Server Books Online. (2)')}
2023-12-15 22:09:29,130  syncdbconnect.py 75 [ERROR] Error Occurred at: ('08001', '[08001] [Microsoft][ODBC Driver 17 for SQL Server]Named Pipes Provider: Could not open a connection to SQL Server [2].  (2) (SQLDriverConnect); [08001] [Microsoft][ODBC Driver 17 for SQL Server]Login timeout expired (0); [08001] [Microsoft][ODBC Driver 17 for SQL Server]A network-related or instance-specific error has occurred while establishing a connection to SQL Server. Server is not found or not accessible. Check if instance name is correct and if SQL Server is configured to allow remote connections. For more information see SQL Server Books Online. (2)') Data Obtained: {'server': 'localhost', 'database': '', 'username': 'admin', 'password': 'localhost', 'e': OperationalError('08001', '[08001] [Microsoft][ODBC Driver 17 for SQL Server]Named Pipes Provider: Could not open a connection to SQL Server [2].  (2) (SQLDriverConnect); [08001] [Microsoft][ODBC Driver 17 for SQL Server]Login timeout expired (0); [08001] [Microsoft][ODBC Driver 17 for SQL Server]A network-related or instance-specific error has occurred while establishing a connection to SQL Server. Server is not found or not accessible. Check if instance name is correct and if SQL Server is configured to allow remote connections. For more information see SQL Server Books Online. (2)')}
2023-12-15 22:09:29,131  syncdbconnect.py 76 [ERROR] Traceback (most recent call last):
  File "C:\Users\Chon791AD14\OneDrive - Ramco Systems Limited\Documents\NLP\PythonScript\Sync_to_Elasticsearch\elasticsearch\elasticsearch\syncdbconnect.py", line 68, in pyodbc_database_connection
    cnxn = pyodbc.connect(
pyodbc.OperationalError: ('08001', '[08001] [Microsoft][ODBC Driver 17 for SQL Server]Named Pipes Provider: Could not open a connection to SQL Server [2].  (2) (SQLDriverConnect); [08001] [Microsoft][ODBC Driver 17 for SQL Server]Login timeout expired (0); [08001] [Microsoft][ODBC Driver 17 for SQL Server]A network-related or instance-specific error has occurred while establishing a connection to SQL Server. Server is not found or not accessible. Check if instance name is correct and if SQL Server is configured to allow remote connections. For more information see SQL Server Books Online. (2)')

2023-12-15 22:09:29,131  syncdbconnect.py 76 [ERROR] Traceback (most recent call last):
  File "C:\Users\Chon791AD14\OneDrive - Ramco Systems Limited\Documents\NLP\PythonScript\Sync_to_Elasticsearch\elasticsearch\elasticsearch\syncdbconnect.py", line 68, in pyodbc_database_connection
    cnxn = pyodbc.connect(
pyodbc.OperationalError: ('08001', '[08001] [Microsoft][ODBC Driver 17 for SQL Server]Named Pipes Provider: Could not open a connection to SQL Server [2].  (2) (SQLDriverConnect); [08001] [Microsoft][ODBC Driver 17 for SQL Server]Login timeout expired (0); [08001] [Microsoft][ODBC Driver 17 for SQL Server]A network-related or instance-specific error has occurred while establishing a connection to SQL Server. Server is not found or not accessible. Check if instance name is correct and if SQL Server is configured to allow remote connections. For more information see SQL Server Books Online. (2)')

